{"name": "test_answer", "status": "failed", "statusDetails": {"message": "AssertionError: assert 4 == 5\n +  where 4 = func(3)", "trace": "def test_answer():\n>       assert func(3) == 5\nE       assert 4 == 5\nE        +  where 4 = func(3)\n\ntest_main.py:11: AssertionError"}, "start": 1603197192231, "stop": 1603197192231, "uuid": "c0181fdb-6aff-4336-a2ef-d4533c13e135", "historyId": "836c02fcef1ff2710be031aa8d84b519", "testCaseId": "62335933eaa07cc43d84c576b9534540", "fullName": "test_main#test_answer", "labels": [{"name": "suite", "value": "test_main"}, {"name": "host", "value": "GJSJ2669-L"}, {"name": "thread", "value": "20316-MainThread"}, {"name": "framework", "value": "pytest"}, {"name": "language", "value": "cpython3"}, {"name": "package", "value": "test_main"}]}